UnknownError                              Traceback (most recent call last)
<ipython-input-22-e33709ae5840> in <module>
      1 # steps_per_epoch parameter
      2 # fit | fit_generator
----> 3 model.fit(train_batches, steps_per_epoch=18, validation_data=valid_batches, validation_steps=3, epochs=35, verbose=2)

/usr/local/lib/python3.8/site-packages/tensorflow/python/keras/engine/training.py in _method_wrapper(self, *args, **kwargs)
    106   def _method_wrapper(self, *args, **kwargs):
    107     if not self._in_multi_worker_mode():  # pylint: disable=protected-access
--> 108       return method(self, *args, **kwargs)
    109 
    110     # Running inside `run_distribute_coordinator` already.

/usr/local/lib/python3.8/site-packages/tensorflow/python/keras/engine/training.py in fit(self, x, y, batch_size, epochs, verbose, callbacks, validation_split, validation_data, shuffle, class_weight, sample_weight, initial_epoch, steps_per_epoch, validation_steps, validation_batch_size, validation_freq, max_queue_size, workers, use_multiprocessing)
   1121                 model=self,
   1122                 steps_per_execution=self._steps_per_execution)
-> 1123           val_logs = self.evaluate(
   1124               x=val_x,
   1125               y=val_y,

/usr/local/lib/python3.8/site-packages/tensorflow/python/keras/engine/training.py in _method_wrapper(self, *args, **kwargs)
    106   def _method_wrapper(self, *args, **kwargs):
    107     if not self._in_multi_worker_mode():  # pylint: disable=protected-access
--> 108       return method(self, *args, **kwargs)
    109 
    110     # Running inside `run_distribute_coordinator` already.

/usr/local/lib/python3.8/site-packages/tensorflow/python/keras/engine/training.py in evaluate(self, x, y, batch_size, verbose, sample_weight, steps, callbacks, max_queue_size, workers, use_multiprocessing, return_dict)
   1377             with trace.Trace('TraceContext', graph_type='test', step_num=step):
   1378               callbacks.on_test_batch_begin(step)
-> 1379               tmp_logs = test_function(iterator)
   1380               if data_handler.should_sync:
   1381                 context.async_wait()

/usr/local/lib/python3.8/site-packages/tensorflow/python/eager/def_function.py in __call__(self, *args, **kwds)
    778       else:
    779         compiler = "nonXla"
--> 780         result = self._call(*args, **kwds)
    781 
    782       new_tracing_count = self._get_tracing_count()

/usr/local/lib/python3.8/site-packages/tensorflow/python/eager/def_function.py in _call(self, *args, **kwds)
    812       # In this case we have not created variables on the first call. So we can
    813       # run the first trace but we should fail if variables are created.
--> 814       results = self._stateful_fn(*args, **kwds)
    815       if self._created_variables:
    816         raise ValueError("Creating variables on a non-first call to a function"

/usr/local/lib/python3.8/site-packages/tensorflow/python/eager/function.py in __call__(self, *args, **kwargs)
   2827     with self._lock:
   2828       graph_function, args, kwargs = self._maybe_define_function(args, kwargs)
-> 2829     return graph_function._filtered_call(args, kwargs)  # pylint: disable=protected-access
   2830 
   2831   @property

/usr/local/lib/python3.8/site-packages/tensorflow/python/eager/function.py in _filtered_call(self, args, kwargs, cancellation_manager)
   1841       `args` and `kwargs`.
   1842     """
-> 1843     return self._call_flat(
   1844         [t for t in nest.flatten((args, kwargs), expand_composites=True)
   1845          if isinstance(t, (ops.Tensor,

/usr/local/lib/python3.8/site-packages/tensorflow/python/eager/function.py in _call_flat(self, args, captured_inputs, cancellation_manager)
   1921         and executing_eagerly):
   1922       # No tape is watching; skip to running the function.
-> 1923       return self._build_call_outputs(self._inference_function.call(
   1924           ctx, args, cancellation_manager=cancellation_manager))
   1925     forward_backward = self._select_forward_and_backward_functions(

/usr/local/lib/python3.8/site-packages/tensorflow/python/eager/function.py in call(self, ctx, args, cancellation_manager)
    543       with _InterpolateFunctionError(self):
    544         if cancellation_manager is None:
--> 545           outputs = execute.execute(
    546               str(self.signature.name),
    547               num_outputs=self._num_outputs,

/usr/local/lib/python3.8/site-packages/tensorflow/python/eager/execute.py in quick_execute(op_name, num_outputs, inputs, attrs, ctx, name)
     57   try:
     58     ctx.ensure_initialized()
---> 59     tensors = pywrap_tfe.TFE_Py_Execute(ctx._handle, device_name, op_name,
     60                                         inputs, attrs, num_outputs)
     61   except core._NotOkStatusException as e:

UnknownError:  UnidentifiedImageError: cannot identify image file <_io.BytesIO object at 0x14ac00ef0>
Traceback (most recent call last):

  File "/usr/local/lib/python3.8/site-packages/tensorflow/python/ops/script_ops.py", line 244, in __call__
    ret = func(*args)

  File "/usr/local/lib/python3.8/site-packages/tensorflow/python/autograph/impl/api.py", line 302, in wrapper
    return func(*args, **kwargs)

  File "/usr/local/lib/python3.8/site-packages/tensorflow/python/data/ops/dataset_ops.py", line 827, in generator_py_func
    values = next(generator_state.get_iterator(iterator_id))

  File "/usr/local/lib/python3.8/site-packages/tensorflow/python/keras/engine/data_adapter.py", line 814, in wrapped_generator
    for data in generator_fn():

  File "/usr/local/lib/python3.8/site-packages/tensorflow/python/keras/engine/data_adapter.py", line 940, in generator_fn
    yield x[i]

  File "/usr/local/lib/python3.8/site-packages/keras_preprocessing/image/iterator.py", line 65, in __getitem__
    return self._get_batches_of_transformed_samples(index_array)

  File "/usr/local/lib/python3.8/site-packages/keras_preprocessing/image/iterator.py", line 227, in _get_batches_of_transformed_samples
    img = load_img(filepaths[j],

  File "/usr/local/lib/python3.8/site-packages/keras_preprocessing/image/utils.py", line 114, in load_img
    img = pil_image.open(io.BytesIO(f.read()))

  File "/usr/local/lib/python3.8/site-packages/PIL/Image.py", line 2930, in open
    raise UnidentifiedImageError(

PIL.UnidentifiedImageError: cannot identify image file <_io.BytesIO object at 0x14ac00ef0>


	 [[{{node PyFunc}}]]
	 [[IteratorGetNext]] [Op:__inference_test_function_6294]

Function call stack:
test_function